Workbook
Name HolidayDates: Holidays!$B$5:$B$60
Name StaffNames: 'Staff Directory'!$B$5:INDEX('Staff Directory'!$B$5:$B$594,MAX(1,COUNTA('Staff Directory'!$B$5:$B$594)))

Sheet README
B2: PPE, SUPPLY & INVENTORY MANAGEMENT SYSTEM
B3: Fiscal Year 2026–27 · Rebuilt formula-driven edition · No macros, no external data connections
B5: HOW THIS WORKBOOK IS DESIGNED
B6: Design principle | C6: Every reporting sheet is driven by live Excel formulas. There are no VBA macros and no external data connections, so the workbook is self-contained, auditable, and safe to keep on a network drive in a regulated environment.
B7: No refresh required | C7: In the previous version the reporting sheets were pasted Power Query output that went stale until manually refreshed. Those sheets are now formulas — they recalculate the moment you enter data.
B8: Three layers | C8: INPUT sheets (you type here) → CALCULATION sheets (formulas only) → DASHBOARD (summary). Never type into a calculation sheet.
B9: Lot traceability | C9: Every receipt carries a Lot Number. Issues are allocated to lots on a First-Expiry-First-Out basis, so a recall can be traced from vendor lot to the staff member who received it.
B11: COLOUR LEGEND
B12: Yellow fill, blue text | C12: INPUT — type here. These are the only cells you should edit.
B13: Black text | C13: Formula — calculated within the same sheet. Do not overwrite.
B14: Green text | C14: Formula — pulls from another sheet. Do not overwrite.
B15: Grey header band | C15: Column headings. Locked layout — do not insert columns inside a table.
B17: SHEET INDEX
B18: Settings | C18: INPUT — alert thresholds, fiscal year start, lead times. Change the numbers here to retune every alert in the workbook.
B19: Items | C19: INPUT — item catalogue: unit rate, standard issue quantity, critical low threshold. The master list every other sheet looks up.
B20: Staff Directory | C20: INPUT — staff ID, name, role, area, contact. Source of truth for staff-linked lookups.
B21: Vendors | C21: INPUT — supplier and service vendor register.
B22: Holidays | C22: INPUT — statutory holidays. Used by WORKDAY() to schedule pickup and reissue dates.
B23: Receipts | C23: INPUT — one row per lot received from a vendor. This is the goods-in ledger.
B24: Issues | C24: INPUT — one row per item dispensed to a staff member. This is the goods-out ledger.
B25: Lot Balance | C25: CALC — per-lot balance with First-Expiry-First-Out allocation, days to expiry, and a recorded-vs-suggested variance check.
B26: Item Balance | C26: CALC — per-item on-hand quantity and value, stock status, earliest expiring lot, and the next lot to issue.
B27: Alerts - Low Stock | C27: CALC — items at or below their critical low threshold. Filter the Alert column.
B28: Alerts - Expiry | C28: CALC — lots expiring inside the alert window, or already expired. Filter the Alert column.
B29: Alerts - Over Quota | C29: CALC — staff members issued more than an item's monthly quota. One row per staff member, item and month.
... B34: Professional Services | C34: INPUT + CALC — service vendor engagements and next scheduled service.
B36: DAILY WORKFLOW
B37: 1. Goods arrive | C37: Add a row to Receipts: date ordered, vendor, lot number, item name, quantity received, expiry date, date received. Everything else fills itself.
B38: 2. Item dispensed | C38: Add a row to Issues: order date, staff ID, item name, quantity, lot number. Enter the Tracking ID once the item is collected — Status flips to Collected automatically.
B39: 3. Check alerts | C39: Open Alerts - Low Stock and Alerts - Expiry. Filter the Alert column to anything other than OK.
B40: 4. Recall received | C40: Open Lot Balance, filter Lot Number to the recalled lot, then filter Issues by that lot to identify every staff member who received it.
B42: KNOWN GAPS CARRIED OVER FROM THE SOURCE WORKBOOK
B43: Critical Low not set for all items | C43: 82 of 127 items have no critical low threshold, so low-stock alerts cannot fire for them. Those cells are highlighted yellow in Items — fill them in to activate the alert. The live count is on the Dashboard under Data Integrity Checks.
B44: Item names are the join key | C44: Lookups match on Item Name text. Renaming an item in Items without updating Receipts and Issues will break its history. Consider adding an Item Code column later.
B45: Recorded lot vs suggested lot | C45: Lot Balance shows both the lot you recorded and the lot First-Expiry-First-Out would have suggested. A non-zero Variance means stock was issued out of expiry order — review it.
B47: IMPORTANT
B48: Data notice | C48: DEMONSTRATION COPY — SAFE TO PUBLISH. All staff names, email addresses, vendor names, branch names and the organisation name in this workbook are synthetic placeholders. Staff names are Lastname###, Firstname### and emails are auto-derived at example.com. No real person, employer or supplier is identified. Quantities, dates, rates and costs are retained so the formula logic can be demonstrated end to end.
B49: Purpose | C49: Published as a portfolio example of a formula-driven Excel inventory system: FEFO lot allocation, expiry and low-stock alerting, per-staff monthly quota enforcement, and auto-generated notice emails. No macros, no external data connections.
B50: CHANGE LOG
B51: Staff ID auto-generated | C51: Staff Directory column A is now a formula: Role-###-Area, sequence numbered per role, with TBD substituted when Area is blank. Do not type into it — add a row with Role and Area and the ID builds itself. Issues staff IDs were rewritten to the new format to keep lookups intact.
...

Sheet Change Log
A1: CHANGE LOG
A2: Changes made to this workbook during the working sessions of 26 July 2026, 28 July 2026 and 4 August 2026. Newest entries at the bottom. This sheet is a record only - nothing else in the workbook depends on it. Read the OPEN ITEMS block below the log before resuming work.
A4: Date | B4: Sheet / Area | C4: Change | D4: Detail | E4: Status
A5: 46229 | B5: Staff Directory | C5: Staff ID auto-generated | D5: Column A is now a formula: role-sequence-area, e.g. PSW-001-A4. Area shows TBD when the Area cell is blank. Sequence numbers match the originals. | E5: Done
A6: 46229 | B6: Issues | C6: Staff IDs updated to the new format | D6: All 73 populated rows in column B were re-mapped to the new role-sequence-area IDs so every lookup on other sheets kept working. | E6: Done
A7: 46229 | B7: Staff Directory | C7: Email auto-generated | D7: Column E is now first.surname@example.com, built from the staff name column. Helper columns H to K hold the cleaned name, first name, surname and greeting name. | E7: Done
A8: 46229 | B8: Staff Directory | C8: Duplicate email flagged | D8: Rows 87 and 88 both produced the same generated email address. Row 87 (a PSW A4 record) was deleted on request and row 88 kept. No duplicate emails or duplicate staff IDs remain across the 243 records. | E8: Resolved
A9: 46229 | B9: Issues | C9: Staff entry switched from ID to name | D9: Column C is now the input with a dropdown of staff names from the Staff Directory. Column B looks the Staff ID up automatically, so you never type an ID again. | E9: Done
A10: 46229 | B10: Settings | C10: Monthly quota setting added | D10: Row 11: monthly issues allowed per staff, set to 1. Monthly quota per staff per item = Standard Issue Qty x this number. | E10: Done
A11: 46229 | B11: Issues | C11: Monthly quota tracking added | D11: Columns R to X: Month, Units This Month for that staff member and item, Monthly Quota, Quota Status, plus three helper columns that de-duplicate breaches. | E11: Done
A12: 46229 | B12: Alerts - Over Quota | C12: New sheet | D12: One row per staff member, item and month over quota, with the excess. Summary band on row 3. Currently 3 breaches across 7 issue rows, 2 staff, 248 excess units. | E12: Done
A13: 46229 | B13: Dashboard | C13: Quota counts added | D13: Row 17 counts staff x item x month breaches. Row 18 counts breaches approved by a team lead. | E13: Done
A14: 46229 | B14: Issues | C14: Team lead approval override | D14: Column Y is an Approved / Not approved dropdown and column Z records who authorised it. Approving a row changes the status to APPROVED BY TL and drops it off the alert sheet. | E14: Done
A15: 46229 | B15: Issues | C15: Row colour rules | D15: Pink row = over quota and not approved. Green row = Tracking ID entered, or over quota but approved. Pink outranks green so a breach is never hidden. | E15: Done
A16: 46229 | B16: Settings | C16: Notice settings added | D16: Rows 12 to 16: pickup location, pickup days, pickup hours, pickup roles and the email sign-off. All wording in the notices comes from these cells. | E16: Done
... A48: 46231 | B48: Issues, Lot Balance, Item Balance, Alerts, Summaries, Dashboard | C48: Nine order lines that had a blank quantity now default to Standard Issue | D48: Rows 1927-1935 were real order lines with Item Name filled but Qty Issued left blank, so they contributed nothing to any balance, quota or cost figure. Under the new formula they now pick up their item's Standard Issue Qty. Total Qty Issued moved from 273,794 to 276,010 (+2,216 units) and total Line Cost from $34,447.70 to $34,601.20 (+$153.50); every other row is unchanged. If any of those nine lines was deliberately zero, enter 0 in its Qty Override cell. | E48: Note
A50: STATUS FOR WHOEVER PICKS THIS UP NEXT
A51: Topic | B51: Where | C51: What you need to know
A52: What this file is | B52: - | C52: This is the ANONYMISED copy of PPE_Supply_Inventory_FY26-27. Every name, contact, address, supplier and price in it is dummy data. The real data lives in the master file, which never leaves the restricted drive. Use this copy for structural work only. | D52: Fact
A53: Masking and restore spec | B53: Restore Guide sheet | C53: Parts 1-7: rules for working in the copy, an inventory of every masked column and what its dummy value encodes, the restore formulas, the find-and-replace reversals, what is still real, and Part 7 the full round-trip cycle with the forward masking formulas. Do not re-derive any of this - it is all on that sheet. | D53: Fact
A54: Money figures are fake | B54: Items, Professional Services and everything derived | C54: Items unit rate and Professional Services cost are masked, so Received Value, Line Cost, Balance Value, Total Cost and every Dashboard money figure in THIS copy are meaningless. Never quote a financial number out of this file. | D54: Warning
A55: Never re-sort five sheets | B55: Staff Directory, Vendors, Items, Office Supplies, Professional Services | C55: Restore and re-masking both key off row position or the dummy value derived from it. Inserting and deleting rows is safe; sorting these five sheets breaks the mapping permanently. | D55: Warning
A56: OPEN - missing receipts | B56: Issues, Receipts, Item Balance | C56: 993 Issues rows name items that have no Receipts entry at all. No lot can be picked for them (Lot Check says 'no receipt on file'), and this is also why Item Balance shows negative on-hand figures. Entering the missing receipts clears both symptoms at once. Biggest outstanding data job. | D56: Open
A57: OPEN - 6 invalid lot overrides | B57: Issues, Lot Override column | C57: Six rows hold a Lot Override that is not a lot of that item - Issues row 7 is one of them (it held the organisation name). Decide per row: clear it so FEFO takes over, or correct it. | D57: Open
A58: OPEN - 21 FEFO deviations | B58: Issues, Lot Check column | C58: 21 rows show 'Override - FEFO says X': a lot was issued out of expiry order. Confirm each was deliberate, or clear the override. Lot Balance Variance flags the 9 lots affected. | D58: Open
A59: OPEN - live file handoff | B59: Live workbook | C59: On 28 July 2026 the Issues FEFO column set (Lot Override, Cum Units, Line Start Unit, FEFO Lot (Auto), Lot At Line End, Lot Check, plus the Lot Number formula) was handed to the session holding the live workbook, matched by header name rather than column letter. Confirm it was actually applied there before relying on it. | D59: Open
A60: OPEN - metadata | B60: File properties | C60: Excel stamps the last author on save, so this file still carries a real user name. Run File > Info > Check for Issues > Inspect Document and remove document properties and personal information before any copy is shared. | D60: Open
A61: Known quirk - mirror offset | B61: Item Balance, Alerts - Low Stock | C61: Item Balance mirrors Items 1:1 down to row 120, then runs 3 rows behind from row 124 onward. Rows 121-123 are deliberately pointed at empty Items rows 598-600 so they render blank. This offset pre-dates the anonymisation work; it loses no items, but do not 'fix' it without checking Alerts - Low Stock, which mirrors Item Balance one row down. | D61: Fact
A62: 46231 | B62: Issues, Lot Balance, Restore Guide | C62: Formula coordination and warning cleanup | D62: Normalized Issues column W first-breach formulas, restored Lot Balance rows 5:2000 to same-row Receipts mirror formulas per the change-log caution, and converted Restore Guide example formulas to text so they no longer act as live external links. Item Balance mirror offset was deliberately left unchanged per the known-quirk note. | E62: Done
A63: 46231 | B63: Restore Guide Part 4 | C63: Text replacement pass applied | D63: Text replacement pass reversed. All organisation names, email domains, branch names, staff names and vendor names in this workbook are synthetic placeholders. The original values are not recorded anywhere in this file. | E63: Done
A64: 46231 | B64: Issues, Change Log | C64: Qty Issued / Qty Override change applied to this workbook from the other session's steps | D64: Matched by header name, not column letter: Qty Override landed in column AO because tblIssues already ran to AN. Sequence followed - override column added to the Table, the 3 rows with a typed quantity different from Standard Issue moved into it (rows 40, 41, 1303), then J5:J1977 filled with the override-first formula. Line Cost in column L already held =IF(OR($J="",$K=""),"",$J*$K) so it was left alone. Verified after: no error values in the used range of Issues, Lot Balance, Item Balance, all three Alerts sheets, Staff Summary, Monthly Summary, Dashboard or this sheet. Totals before and after are in row 48 - they do not match, because nine blank-quantity rows now default to Standard Issue. | E64: Done
A65: 46231 | B65: Issues | C65: Over-quota row highlight now covers the whole row | D65: The pink rule was applied to a patchwork of ranges (A5:Z23, A30:Z42, U16:U1926, G1927:I1977 and 17 others), so on most breach rows only part of the row turned pink and the columns outside those blocks stayed green or unfilled. Replaced with a single rule on A5:AO1977, =$U5="⚠ OVER QUOTA", pink fill #FCE4EC with dark red text, priority 1 so it still outranks the green collected rule. The green rule was rebuilt on the same full-width range (it stopped at AH, so the six FEFO columns and Qty Override were never shaded). 141 rows are currently over quota and 2 are approved by a team lead. A stale rule on P43:P46 keyed to column J = "✅" was deleted at the same time - it could never fire once J became a quantity formula. Five rules remain on the sheet: over-quota row, over-quota status cell, approved status cell, Tracking ID cell, collected row. | E65: Done
A66: 46231 | B66: Staff Directory, Issues, Vendors, Items, Receipts, Office Supplies, Settings, README | C66: Full anonymisation for public release | D66: 265 unique staff names replaced with Lastname###, Firstname### placeholders across Staff Directory (590 rows) and Issues (1,973 rows). 295 email formulas repointed to @example.com. Branch wording reset to Sample Branch in Settings C12 and 1,973 Issues notice-body formulas; sign-off reset to Sample Supply Team. 14 vendor records plus 62 Receipts and 22 Office Supplies rows replaced with fictional vendor names; retailer brands inside item names replaced consistently across Items, Receipts, Issues and Office Supplies so the join keys still match. File metadata cleared. No formula logic was altered - only input cells and two hardcoded string literals. | E66: Done
A67: 46231 | B67: Staff Directory, Restore Guide | C67: Area codes masked; Restore Guide sheet removed | D67: The 10 real service-area codes in Staff Directory column D were replaced with generic codes A1-A10 across 242 rows, removing the residual re-identification risk noted in the old Restore Guide Part 5 (area codes plus per-staff transaction behaviour). Staff IDs in Staff Directory column A and Issues column B are formulas and rebuilt themselves; no formula hardcoded an area code, so nothing else needed changing. The Restore Guide sheet was then deleted: it documented the previous row-number-based masking scheme, which no longer matches this file, and it published the masking method itself. It is retained in the owner's private master copy. Earlier Change Log rows still reference it as history. | E67: Done
A68: =DATE(2026,8,4) -> 46238 | B68: Staff Directory, Professional Services | C68: Formula audit - broken email column and missing total repaired | D68: Workbook-wide audit of ~148,000 formula cells across all 19 sheets. Staff Directory E5:E299 held the only error values in the file - 295 #REF! cells, because the email formula still referenced first-name and last-name columns deleted during an earlier restructure. Rebuilt as =IF($B5="","",IFERROR(LOWER(SUBSTITUTE(TRIM(MID($B5,FIND(",",$B5)+1,255))," ",".")&"."&SUBSTITUTE(TRIM(LEFT($B5,FIND(",",$B5)-1))," ","."))&"@example.com","")), parsing the existing Lastname, Firstname value in column B. 266 addresses now generate, 265 of them unique - the one duplicate (rows 89 and 90) is a genuinely duplicated directory name, not a formula fault, and remains open. Also cleared 29 stale email formulas in E271:E299 that ran past the last staff row, and 324 stray zero values in B271:B594 that were inflating COUNTA-based staff counts. On Professional Services, added the missing =SUM($E$5:$E$200) beside the Total service spend label in E202, and appended &"" inside the column H and I vendor lookups so an empty Vendors record returns blank rather than 0. Verified after: full recalculation, then a used-range scan of all 19 sheets returned zero error cells. | E68: Done
A69: =DATE(2026,8,4) -> 46238 | B69: README, Change Log | C69: Documentation refreshed to match the current file | D69: Corrected four stale statements on the README sheet: the critical-low gap now reads 82 of 127 items (was 73 of 116); Table extents corrected to Issues A4:AO1977 and Receipts A4:K192 (were quoted as A4:AH3000 and A4:K1000); the caution note no longer tells the reader to keep backup sheets, since Issues (pre-Table), Receipts (pre-Table) and Lot Balance (backup) are not present in this copy; and the Professional Services description now notes that data ends at row 200 with the spend total in row 202. Prepared repository documentation for public release on GitHub. | E69: Done

Sheet Settings
A1: SETTINGS
A2: Change these values to retune every alert and schedule in the workbook.
B4: Setting | C4: Value | D4: What it controls
B5: Expiry alert window (days) | C5: 180 | D5: A lot appears on Alerts - Expiry when days to expiry falls to or below this.
B6: Expiry critical window (days) | C6: 30 | D6: A lot is flagged CRITICAL rather than EXPIRING inside this window.
B7: Low stock watch multiplier | C7: 1.25 | D7: An item is flagged WATCH when on hand is below Critical Low multiplied by this.
B8: Fiscal year start | C8: 46113 | D8: First day of the fiscal year. Drives the Monthly Summary calendar.
B9: Pickup lead time (workdays) | C9: 6 | D9: Workdays added to an order date to set the pickup date, skipping holidays.
B10: Reissue cycle (workdays) | C10: 28 | D10: Workdays added to a pickup date to set the next scheduled issue.
B11: Monthly issues allowed per staff | C11: 1 | D11: Monthly quota per staff per item = Standard Issue Qty x this. A staff member above that in a calendar month is flagged on Issues and listed on Alerts - Over Quota.
B12: Pickup location | C12: Sample Branch | D12: Named in the pickup notice email on Issues.
B13: Pickup days | C13: Wednesday to Friday | D13: Collection days quoted in the pickup notice.
B14: Pickup hours | C14: 9:00 am to 4:00 pm | D14: Collection hours quoted in the pickup notice.
B15: Pickup roles | C15: PSW | D15: Roles that collect in person at the branch. Any other role, including RN, gets the dispatched / in transit notice.
B16: Email sign-off | C16: Sample Supply Team | D16: Signature line at the foot of the pickup and dispatch notices.

Sheet Items
A1: ITEM CATALOGUE
A2: INPUT. Master list of every PPE, office, and equipment item. Every other sheet looks up against Item Name.
A4: Item Name | B4: Item Type | C4: Size | D4: Unit Rate | E4: Standard Issue Qty | F4: Critical Low | G4: Group | H4: Pack / Unit Description | I4: Notes
A5: 1804 N95 Mask | B5: Masks | C5: One Size | D5: 2.05 | E5: 5 | F5: 500 | G5: PPE
A6: 1860 N95 Mask | B6: Masks | C6: One Size | D6: 2.05 | E6: 5 | F6: 500 | G6: PPE
A7: 1860S N95 Mask | B7: Masks | C7: One Size | D7: 2.05 | E7: 5 | F7: 500 | G7: PPE
A8: 1870 N95 Mask | B8: Masks | C8: One Size | D8: 2.05 | E8: 5 | F8: 500 | G8: PPE
A9: 1870+ N95 Mask | B9: Masks | C9: One Size | D9: 2.05 | E9: 5 | F9: 500 | G9: PPE
A10: 8110S N95 Mask | B10: Masks | C10: One Size | D10: 1.45 | E10: 5 | F10: 500 | G10: PPE
A11: 8210 N95 Mask | B11: Masks | C11: One Size | D11: 1.45 | E11: 5 | F11: 500 | G11: PPE
A12: 9210+ N95 Mask | B12: Masks | C12: One Size | D12: 1.45 | E12: 5 | F12: 500 | G12: PPE
A13: CAN95 | B13: Masks | C13: One Size | D13: 1.35 | E13: 5 | F13: 500 | G13: PPE
A14: CAN99 | B14: Masks | C14: One Size | D14: 1.35 | E14: 5 | F14: 500 | G14: PPE
A15: Coverall with hood - VENCVCA300N | B15: IPAC | C15: LG/XL | D15: 3.29 | E15: 4 | F15: 100 | G15: PPE
A16: Coverall with shoe cover | B16: IPAC | C16: Standard | D16: 5.16 | E16: 1 | F16: 500 | G16: PPE
A17: Disinfectant Wipes | B17: Wipes | C17: 80 | D17: 0.1 | E17: 80 | F17: 50000 | G17: PPE
A18: Ear Savers | B18: Accessories | C18: One Size | D18: 3 | E18: 1 | G18: PPE
A19: Epinephrine | B19: Drug | C19: 1 Amp | D19: 5.9 | E19: 2 | G19: PPE
A20: Face Shields | B20: Eye Protection | C20: One Size | D20: 7 | E20: 1 | G20: PPE
A21: Gloves - Large | B21: Gloves | C21: Large | D21: 0.055 | E21: 500 | F21: 4000 | G21: PPE
A22: Gloves - Medium | B22: Gloves | C22: Medium | D22: 0.055 | E22: 500 | F22: 7500 | G22: PPE
A23: Gloves - Small | B23: Gloves | C23: Small | D23: 0.055 | E23: 500 | F23: 4000 | G23: PPE
A24: Gloves - Small/100 | B24: Gloves | C24: Small | D24: 0.055 | E24: 500 | F24: 1000 | G24: PPE
A25: Gloves - X-Large | B25: Gloves | C25: X-Large | D25: 0.055 | E25: 500 | F25: 4000 | G25: PPE
A26: Gloves - X-Small | B26: Gloves | C26: X-Small | D26: 0.055 | E26: 500 | F26: 4000 | G26: PPE
A27: Goggles | B27: Eye Protection | C27: One Size | D27: 10 | E27: 1 | G27: PPE
A28: Hand Sanitizer | B28: Sanitizer | C28: 118 ML | D28: 4.49 | E28: 2 | F28: 200 | G28: PPE
A29: ICE Cleats -Small | B29: PPE | C29: Small | D29: 145.98 | E29: 1 | G29: PPE
A30: ICE Cleats-Large | B30: PPE | C30: Large | D30: 145.98 | E30: 1 | G30: PPE
A31: ICE Cleats-Medium | B31: PPE | C31: Medium | D31: 145.98 | E31: 1 | G31: PPE
A32: ICE Cleats-X-Large | B32: PPE | C32: X-Large | D32: 145.98 | E32: 1 | G32: PPE
A33: Infestation Supplies | B33: IPAC | C33: One Size | D33: 145.98 | E33: 4 | G33: PPE
A34: Level 1/2 - Water resistant Blue Gowns | B34: Apparel | C34: One Size | D34: 3 | E34: 5 | F34: 200 | G34: PPE
A35: Level 1/2 - Yellow Gown | B35: Apparel | C35: One Size | D35: 3 | E35: 5 | F35: 200 | G35: PPE
A36: narrative progress notes | B36: Documents | C36: Standard | D36: 0 | E36: 20 | G36: PPE
A37: Nurse on Duty Pass | B37: Documents | C37: Standard | D37: 0 | E37: 1 | G37: PPE
A38: Personal Care activity Sheets | B38: HS Charts | C38: Standard | D38: 0 | E38: 20 | G38: PPE
A39: PSW Charts | B39: Sample Org Charts PSW | C39: Standard | D39: 0 | E39: 5 | G39: PPE
A40: Shoe Covers | B40: IPAC | C40: Regular | D40: 0.2 | E40: 50 | F40: 300 | G40: PPE
A41: Surgical Masks | B41: Masks | C41: One Size | D41: 0.25 | E41: 50 | F41: 1000 | G41: PPE
...

Sheet Staff Directory
A1: STAFF DIRECTORY
A2: INPUT. Source of truth for staff-linked lookups. Staff ID must be unique.
A4: Staff ID | B4: Staff Name | C4: Role | D4: Area | E4: Email | F4: Contact | G4: Address
A5: =IF($C5="","",$C5&"-"&TEXT(COUNTIF($C$5:$C5,$C5),"000")&"-"&IF($D5="","TBD",$D5)) -> RN-001-A1 | B5: Lastname001, Firstname001 | C5: RN | D5: A1 | E5: =IF($B5="","",IFERROR(LOWER(SUBSTITUTE(TRIM(MID($B5,FIND(",",$B5)+1,255))," ",".")&"."&SUBSTITUTE(TRIM(LEFT($B5,FIND(",",$B5)-1))," ","."))&"@example.com","")) -> firstname001.lastname001@example.com
A6: =IF($C6="","",$C6&"-"&TEXT(COUNTIF($C$5:$C6,$C6),"000")&"-"&IF($D6="","TBD",$D6)) -> RN-002-A1 | B6: Lastname002, Firstname002 | C6: RN | D6: A1 | E6: =IF($B6="","",IFERROR(LOWER(SUBSTITUTE(TRIM(MID($B6,FIND(",",$B6)+1,255))," ",".")&"."&SUBSTITUTE(TRIM(LEFT($B6,FIND(",",$B6)-1))," ","."))&"@example.com","")) -> firstname002.lastname002@example.com
A7: =IF($C7="","",$C7&"-"&TEXT(COUNTIF($C$5:$C7,$C7),"000")&"-"&IF($D7="","TBD",$D7)) -> RN-003-A1 | B7: Lastname003, Firstname003 | C7: RN | D7: A1 | E7: =IF($B7="","",IFERROR(LOWER(SUBSTITUTE(TRIM(MID($B7,FIND(",",$B7)+1,255))," ",".")&"."&SUBSTITUTE(TRIM(LEFT($B7,FIND(",",$B7)-1))," ","."))&"@example.com","")) -> firstname003.lastname003@example.com
A8: =IF($C8="","",$C8&"-"&TEXT(COUNTIF($C$5:$C8,$C8),"000")&"-"&IF($D8="","TBD",$D8)) -> RN-004-A2 | B8: Lastname004, Firstname004 | C8: RN | D8: A2 | E8: =IF($B8="","",IFERROR(LOWER(SUBSTITUTE(TRIM(MID($B8,FIND(",",$B8)+1,255))," ",".")&"."&SUBSTITUTE(TRIM(LEFT($B8,FIND(",",$B8)-1))," ","."))&"@example.com","")) -> firstname004.lastname004@example.com
A9: =IF($C9="","",$C9&"-"&TEXT(COUNTIF($C$5:$C9,$C9),"000")&"-"&IF($D9="","TBD",$D9)) -> RN-005-A1 | B9: Lastname005, Firstname005 | C9: RN | D9: A1 | E9: =IF($B9="","",IFERROR(LOWER(SUBSTITUTE(TRIM(MID($B9,FIND(",",$B9)+1,255))," ",".")&"."&SUBSTITUTE(TRIM(LEFT($B9,FIND(",",$B9)-1))," ","."))&"@example.com","")) -> firstname005.lastname005@example.com
A10: =IF($C10="","",$C10&"-"&TEXT(COUNTIF($C$5:$C10,$C10),"000")&"-"&IF($D10="","TBD",$D10)) -> RN-006-A1 | B10: Lastname006, Firstname006 | C10: RN | D10: A1 | E10: =IF($B10="","",IFERROR(LOWER(SUBSTITUTE(TRIM(MID($B10,FIND(",",$B10)+1,255))," ",".")&"."&SUBSTITUTE(TRIM(LEFT($B10,FIND(",",$B10)-1))," ","."))&"@example.com","")) -> firstname006.lastname006@example.com
A11: =IF($C11="","",$C11&"-"&TEXT(COUNTIF($C$5:$C11,$C11),"000")&"-"&IF($D11="","TBD",$D11)) -> RN-007-A1 | B11: Lastname007, Firstname007 | C11: RN | D11: A1 | E11: =IF($B11="","",IFERROR(LOWER(SUBSTITUTE(TRIM(MID($B11,FIND(",",$B11)+1,255))," ",".")&"."&SUBSTITUTE(TRIM(LEFT($B11,FIND(",",$B11)-1))," ","."))&"@example.com","")) -> firstname007.lastname007@example.com
A12: =IF($C12="","",$C12&"-"&TEXT(COUNTIF($C$5:$C12,$C12),"000")&"-"&IF($D12="","TBD",$D12)) -> RN-008-A1 | B12: Lastname008, Firstname008 | C12: RN | D12: A1 | E12: =IF($B12="","",IFERROR(LOWER(SUBSTITUTE(TRIM(MID($B12,FIND(",",$B12)+1,255))," ",".")&"."&SUBSTITUTE(TRIM(LEFT($B12,FIND(",",$B12)-1))," ","."))&"@example.com","")) -> firstname008.lastname008@example.com
A13: =IF($C13="","",$C13&"-"&TEXT(COUNTIF($C$5:$C13,$C13),"000")&"-"&IF($D13="","TBD",$D13)) -> RN-009-A2 | B13: Lastname009, Firstname009 | C13: RN | D13: A2 | E13: =IF($B13="","",IFERROR(LOWER(SUBSTITUTE(TRIM(MID($B13,FIND(",",$B13)+1,255))," ",".")&"."&SUBSTITUTE(TRIM(LEFT($B13,FIND(",",$B13)-1))," ","."))&"@example.com","")) -> firstname009.lastname009@example.com
A14: =IF($C14="","",$C14&"-"&TEXT(COUNTIF($C$5:$C14,$C14),"000")&"-"&IF($D14="","TBD",$D14)) -> RN-010-A2 | B14: Lastname010, Firstname010 | C14: RN | D14: A2 | E14: =IF($B14="","",IFERROR(LOWER(SUBSTITUTE(TRIM(MID($B14,FIND(",",$B14)+1,255))," ",".")&"."&SUBSTITUTE(TRIM(LEFT($B14,FIND(",",$B14)-1))," ","."))&"@example.com","")) -> firstname010.lastname010@example.com
A15: =IF($C15="","",$C15&"-"&TEXT(COUNTIF($C$5:$C15,$C15),"000")&"-"&IF($D15="","TBD",$D15)) -> RN-011-A2 | B15: Lastname011, Firstname011 | C15: RN | D15: A2 | E15: =IF($B15="","",IFERROR(LOWER(SUBSTITUTE(TRIM(MID($B15,FIND(",",$B15)+1,255))," ",".")&"."&SUBSTITUTE(TRIM(LEFT($B15,FIND(",",$B15)-1))," ","."))&"@example.com","")) -> firstname011.lastname011@example.com
A16: =IF($C16="","",$C16&"-"&TEXT(COUNTIF($C$5:$C16,$C16),"000")&"-"&IF($D16="","TBD",$D16)) -> RPN-001-A1 | B16: Lastname012, Firstname012 | C16: RPN | D16: A1 | E16: =IF($B16="","",IFERROR(LOWER(SUBSTITUTE(TRIM(MID($B16,FIND(",",$B16)+1,255))," ",".")&"."&SUBSTITUTE(TRIM(LEFT($B16,FIND(",",$B16)-1))," ","."))&"@example.com","")) -> firstname012.lastname012@example.com
... A58: =IF($C58="","",$C58&"-"&TEXT(COUNTIF($C$5:$C58,$C58),"000")&"-"&IF($D58="","TBD",$D58)) -> OEE-001-A3 | B58: Lastname054, Firstname054 | C58: OEE | D58: A3 | E58: =IF($B58="","",IFERROR(LOWER(SUBSTITUTE(TRIM(MID($B58,FIND(",",$B58)+1,255))," ",".")&"."&SUBSTITUTE(TRIM(LEFT($B58,FIND(",",$B58)-1))," ","."))&"@example.com","")) -> firstname054.lastname054@example.com
A59: =IF($C59="","",$C59&"-"&TEXT(COUNTIF($C$5:$C59,$C59),"000")&"-"&IF($D59="","TBD",$D59)) -> RN-047-TBD | B59: Lastname055, Firstname055 | C59: RN | E59: =IF($B59="","",IFERROR(LOWER(SUBSTITUTE(TRIM(MID($B59,FIND(",",$B59)+1,255))," ",".")&"."&SUBSTITUTE(TRIM(LEFT($B59,FIND(",",$B59)-1))," ","."))&"@example.com","")) -> firstname055.lastname055@example.com
A60: =IF($C60="","",$C60&"-"&TEXT(COUNTIF($C$5:$C60,$C60),"000")&"-"&IF($D60="","TBD",$D60)) -> RN-048-A1 | B60: Lastname056, Firstname056 | C60: RN | D60: A1 | E60: =IF($B60="","",IFERROR(LOWER(SUBSTITUTE(TRIM(MID($B60,FIND(",",$B60)+1,255))," ",".")&"."&SUBSTITUTE(TRIM(LEFT($B60,FIND(",",$B60)-1))," ","."))&"@example.com","")) -> firstname056.lastname056@example.com
A61: =IF($C61="","",$C61&"-"&TEXT(COUNTIF($C$5:$C61,$C61),"000")&"-"&IF($D61="","TBD",$D61)) -> ADMN CO-001-TBD | B61: Lastname057, Firstname057 | C61: ADMN CO | E61: =IF($B61="","",IFERROR(LOWER(SUBSTITUTE(TRIM(MID($B61,FIND(",",$B61)+1,255))," ",".")&"."&SUBSTITUTE(TRIM(LEFT($B61,FIND(",",$B61)-1))," ","."))&"@example.com","")) -> firstname057.lastname057@example.com
A62: =IF($C62="","",$C62&"-"&TEXT(COUNTIF($C$5:$C62,$C62),"000")&"-"&IF($D62="","TBD",$D62)) -> RN-049-A1 | B62: Lastname058, Firstname058 | C62: RN | D62: A1 | E62: =IF($B62="","",IFERROR(LOWER(SUBSTITUTE(TRIM(MID($B62,FIND(",",$B62)+1,255))," ",".")&"."&SUBSTITUTE(TRIM(LEFT($B62,FIND(",",$B62)-1))," ","."))&"@example.com","")) -> firstname058.lastname058@example.com
A63: =IF($C63="","",$C63&"-"&TEXT(COUNTIF($C$5:$C63,$C63),"000")&"-"&IF($D63="","TBD",$D63)) -> RN-050-A1 | B63: Lastname059, Firstname059 | C63: RN | D63: A1 | E63: =IF($B63="","",IFERROR(LOWER(SUBSTITUTE(TRIM(MID($B63,FIND(",",$B63)+1,255))," ",".")&"."&SUBSTITUTE(TRIM(LEFT($B63,FIND(",",$B63)-1))," ","."))&"@example.com","")) -> firstname059.lastname059@example.com
A64: =IF($C64="","",$C64&"-"&TEXT(COUNTIF($C$5:$C64,$C64),"000")&"-"&IF($D64="","TBD",$D64)) -> RN-051-A2 | B64: Lastname060, Firstname060 | C64: RN | D64: A2 | E64: =IF($B64="","",IFERROR(LOWER(SUBSTITUTE(TRIM(MID($B64,FIND(",",$B64)+1,255))," ",".")&"."&SUBSTITUTE(TRIM(LEFT($B64,FIND(",",$B64)-1))," ","."))&"@example.com","")) -> firstname060.lastname060@example.com
A65: =IF($C65="","",$C65&"-"&TEXT(COUNTIF($C$5:$C65,$C65),"000")&"-"&IF($D65="","TBD",$D65)) -> PSW-001-A4 | B65: Lastname061, Firstname061 | C65: PSW | D65: A4 | E65: =IF($B65="","",IFERROR(LOWER(SUBSTITUTE(TRIM(MID($B65,FIND(",",$B65)+1,255))," ",".")&"."&SUBSTITUTE(TRIM(LEFT($B65,FIND(",",$B65)-1))," ","."))&"@example.com","")) -> firstname061.lastname061@example.com
A66: =IF($C66="","",$C66&"-"&TEXT(COUNTIF($C$5:$C66,$C66),"000")&"-"&IF($D66="","TBD",$D66)) -> PSW-002-A4 | B66: Lastname062, Firstname062 | C66: PSW | D66: A4 | E66: =IF($B66="","",IFERROR(LOWER(SUBSTITUTE(TRIM(MID($B66,FIND(",",$B66)+1,255))," ",".")&"."&SUBSTITUTE(TRIM(LEFT($B66,FIND(",",$B66)-1))," ","."))&"@example.com","")) -> firstname062.lastname062@example.com
A67: =IF($C67="","",$C67&"-"&TEXT(COUNTIF($C$5:$C67,$C67),"000")&"-"&IF($D67="","TBD",$D67)) -> PSW-003-A4 | B67: Lastname063, Firstname063 | C67: PSW | D67: A4 | E67: =IF($B67="","",IFERROR(LOWER(SUBSTITUTE(TRIM(MID($B67,FIND(",",$B67)+1,255))," ",".")&"."&SUBSTITUTE(TRIM(LEFT($B67,FIND(",",$B67)-1))," ","."))&"@example.com","")) -> firstname063.lastname063@example.com
A68: =IF($C68="","",$C68&"-"&TEXT(COUNTIF($C$5:$C68,$C68),"000")&"-"&IF($D68="","TBD",$D68)) -> PSW-004-A4 | B68: Lastname064, Firstname064 | C68: PSW | D68: A4 | E68: =IF($B68="","",IFERROR(LOWER(SUBSTITUTE(TRIM(MID($B68,FIND(",",$B68)+1,255))," ",".")&"."&SUBSTITUTE(TRIM(LEFT($B68,FIND(",",$B68)-1))," ","."))&"@example.com","")) -> firstname064.lastname064@example.com
A69: =IF($C69="","",$C69&"-"&TEXT(COUNTIF($C$5:$C69,$C69),"000")&"-"&IF($D69="","TBD",$D69)) -> PSW-005-A5 | B69: Lastname065, Firstname065 | C69: PSW | D69: A5 | E69: =IF($B69="","",IFERROR(LOWER(SUBSTITUTE(TRIM(MID($B69,FIND(",",$B69)+1,255))," ",".")&"."&SUBSTITUTE(TRIM(LEFT($B69,FIND(",",$B69)-1))," ","."))&"@example.com","")) -> firstname065.lastname065@example.com
A70: =IF($C70="","",$C70&"-"&TEXT(COUNTIF($C$5:$C70,$C70),"000")&"-"&IF($D70="","TBD",$D70)) -> PSW-006-A6 | B70: Lastname066, Firstname066 | C70: PSW | D70: A6 | E70: =IF($B70="","",IFERROR(LOWER(SUBSTITUTE(TRIM(MID($B70,FIND(",",$B70)+1,255))," ",".")&"."&SUBSTITUTE(TRIM(LEFT($B70,FIND(",",$B70)-1))," ","."))&"@example.com","")) -> firstname066.lastname066@example.com
A71: =IF($C71="","",$C71&"-"&TEXT(COUNTIF($C$5:$C71,$C71),"000")&"-"&IF($D71="","TBD",$D71)) -> PSW-007-A5 | B71: Lastname067, Firstname067 | C71: PSW | D71: A5 | E71: =IF($B71="","",IFERROR(LOWER(SUBSTITUTE(TRIM(MID($B71,FIND(",",$B71)+1,255))," ",".")&"."&SUBSTITUTE(TRIM(LEFT($B71,FIND(",",$B71)-1))," ","."))&"@example.com","")) -> firstname067.lastname067@example.com
A72: =IF($C72="","",$C72&"-"&TEXT(COUNTIF($C$5:$C72,$C72),"000")&"-"&IF($D72="","TBD",$D72)) -> PSW-008-A6 | B72: Lastname068, Firstname068 | C72: PSW | D72: A6 | E72: =IF($B72="","",IFERROR(LOWER(SUBSTITUTE(TRIM(MID($B72,FIND(",",$B72)+1,255))," ",".")&"."&SUBSTITUTE(TRIM(LEFT($B72,FIND(",",$B72)-1))," ","."))&"@example.com","")) -> firstname068.lastname068@example.com
A73: =IF($C73="","",$C73&"-"&TEXT(COUNTIF($C$5:$C73,$C73),"000")&"-"&IF($D73="","TBD",$D73)) -> PSW-009-A5 | B73: Lastname069, Firstname069 | C73: PSW | D73: A5 | E73: =IF($B73="","",IFERROR(LOWER(SUBSTITUTE(TRIM(MID($B73,FIND(",",$B73)+1,255))," ",".")&"."&SUBSTITUTE(TRIM(LEFT($B73,FIND(",",$B73)-1))," ","."))&"@example.com","")) -> firstname069.lastname069@example.com
... A135: =IF($C135="","",$C135&"-"&TEXT(COUNTIF($C$5:$C135,$C135),"000")&"-"&IF($D135="","TBD",$D135)) -> PSW-070-A6 | B135: Lastname130, Firstname130 | C135: PSW | D135: A6 | E135: =IF($B135="","",IFERROR(LOWER(SUBSTITUTE(TRIM(MID($B135,FIND(",",$B135)+1,255))," ",".")&"."&SUBSTITUTE(TRIM(LEFT($B135,FIND(",",$B135)-1))," ","."))&"@example.com","")) -> firstname130.lastname130@example.com
A136: =IF($C136="","",$C136&"-"&TEXT(COUNTIF($C$5:$C136,$C136),"000")&"-"&IF($D136="","TBD",$D136)) -> PSW-071-TBD | B136: Lastname131, Firstname131 | C136: PSW | E136: =IF($B136="","",IFERROR(LOWER(SUBSTITUTE(TRIM(MID($B136,FIND(",",$B136)+1,255))," ",".")&"."&SUBSTITUTE(TRIM(LEFT($B136,FIND(",",$B136)-1))," ","."))&"@example.com","")) -> firstname131.lastname131@example.com
A137: =IF($C137="","",$C137&"-"&TEXT(COUNTIF($C$5:$C137,$C137),"000")&"-"&IF($D137="","TBD",$D137)) -> PSW-072-A5 | B137: Lastname132, Firstname132 | C137: PSW | D137: A5 | E137: =IF($B137="","",IFERROR(LOWER(SUBSTITUTE(TRIM(MID($B137,FIND(",",$B137)+1,255))," ",".")&"."&SUBSTITUTE(TRIM(LEFT($B137,FIND(",",$B137)-1))," ","."))&"@example.com","")) -> firstname132.lastname132@example.com
A138: =IF($C138="","",$C138&"-"&TEXT(COUNTIF($C$5:$C138,$C138),"000")&"-"&IF($D138="","TBD",$D138)) -> PSW-073-A5 | B138: Lastname133, Firstname133 | C138: PSW | D138: A5 | E138: =IF($B138="","",IFERROR(LOWER(SUBSTITUTE(TRIM(MID($B138,FIND(",",$B138)+1,255))," ",".")&"."&SUBSTITUTE(TRIM(LEFT($B138,FIND(",",$B138)-1))," ","."))&"@example.com","")) -> firstname133.lastname133@example.com
A139: =IF($C139="","",$C139&"-"&TEXT(COUNTIF($C$5:$C139,$C139),"000")&"-"&IF($D139="","TBD",$D139)) -> PSW-074-A5 | B139: Lastname134, Firstname134 | C139: PSW | D139: A5 | E139: =IF($B139="","",IFERROR(LOWER(SUBSTITUTE(TRIM(MID($B139,FIND(",",$B139)+1,255))," ",".")&"."&SUBSTITUTE(TRIM(LEFT($B139,FIND(",",$B139)-1))," ","."))&"@example.com","")) -> firstname134.lastname134@example.com
A140: =IF($C140="","",$C140&"-"&TEXT(COUNTIF($C$5:$C140,$C140),"000")&"-"&IF($D140="","TBD",$D140)) -> PSW-075-A7 | B140: Lastname135, Firstname135 | C140: PSW | D140: A7 | E140: =IF($B140="","",IFERROR(LOWER(SUBSTITUTE(TRIM(MID($B140,FIND(",",$B140)+1,255))," ",".")&"."&SUBSTITUTE(TRIM(LEFT($B140,FIND(",",$B140)-1))," ","."))&"@example.com","")) -> firstname135.lastname135@example.com
A141: =IF($C141="","",$C141&"-"&TEXT(COUNTIF($C$5:$C141,$C141),"000")&"-"&IF($D141="","TBD",$D141)) -> PSW-076-A5 | B141: Lastname136, Firstname136 | C141: PSW | D141: A5 | E141: =IF($B141="","",IFERROR(LOWER(SUBSTITUTE(TRIM(MID($B141,FIND(",",$B141)+1,255))," ",".")&"."&SUBSTITUTE(TRIM(LEFT($B141,FIND(",",$B141)-1))," ","."))&"@example.com","")) -> firstname136.lastname136@example.com
A142: =IF($C142="","",$C142&"-"&TEXT(COUNTIF($C$5:$C142,$C142),"000")&"-"&IF($D142="","TBD",$D142)) -> PSW-077-A7 | B142: Lastname137, Firstname137 | C142: PSW | D142: A7 | E142: =IF($B142="","",IFERROR(LOWER(SUBSTITUTE(TRIM(MID($B142,FIND(",",$B142)+1,255))," ",".")&"."&SUBSTITUTE(TRIM(LEFT($B142,FIND(",",$B142)-1))," ","."))&"@example.com","")) -> firstname137.lastname137@example.com
A143: =IF($C143="","",$C143&"-"&TEXT(COUNTIF($C$5:$C143,$C143),"000")&"-"&IF($D143="","TBD",$D143)) -> PSW-078-A4 | B143: Lastname138, Firstname138 | C143: PSW | D143: A4 | E143: =IF($B143="","",IFERROR(LOWER(SUBSTITUTE(TRIM(MID($B143,FIND(",",$B143)+1,255))," ",".")&"."&SUBSTITUTE(TRIM(LEFT($B143,FIND(",",$B143)-1))," ","."))&"@example.com","")) -> firstname138.lastname138@example.com
...

Sheet Vendors
A1: VENDOR REGISTER
A2: INPUT. Supply vendors and professional service vendors.
A4: Vendor Name | B4: Group | C4: Service Category | D4: Scope of Work | E4: Email | F4: Contact No | G4: Service Frequency | H4: Address
A5: Acme Medical Supply | B5: Supply | C5: Epinephrine Supply | D5: Epinephrine
A6: Global PPE Distributors | B6: Supply | C6: PPE Supplies | D6: Gloves, Mask, Gown, Coverall
A7: Northwind Office Supply | B7: Supply | C7: Minor PPE Supplies | D7: Hand Sanitizer, Disinfectant Wipes
A8: Admin Coordinator | B8: Supply | C8: Sample Org Charts | D8: Intake Files
A9: Internal Health & Safety | B9: Supply | C9: Ice Cleats | D9: Safety Gears
A10: Contoso Online Retail | B10: Supply | C10: Filing | D10: Folders
A11: Contoso Online Retail | B11: Supply | C11: Labels | D11: Top Sample Org Chart Label
A12: Contoso Online Retail | B12: Supply | C12: Labels | D12: Bottom Sample Org Chart Label
A13: Homecare Forms Co | B13: Supply | C13: Forms Supply | D13: DNR & EDITH
A14: Regional Supply Co | B14: Supply | C14: PPE Supplies | D14: Gloves, Mask, Gown, Coverall
A15: Alpha Facilities Services | B15: Pro Svc Vendor | C15: Handyman | D15: Wall Mounting, Furniture repair, TV mounting, Rack Anchoring
A16: Beta Locksmith Services | B16: Pro Svc Vendor | C16: Locksmith | D16: 3 Keypad locks and 5 deadbolt locks
A17: Clearwater Water Services | B17: Pro Svc Vendor | C17: Office Water Supply | D17: Drinking Water supply | G17: 30
A18: Delta Print Services | B18: Pro Svc Vendor | C18: Printer Maintenance | D18: Printer Services
A19: Secure Records Storage | B19: Pro Svc Vendor | C19: Record disposal & Storage | D19: Off site Shredding Services | G19: 30
A20: 0
A21: 0
A22: 0
A23: 0
A24: 0
A25: 0
A26: 0
A27: 0
A28: 0
A29: 0
A30: 0
A31: 0
... A100: 0

Sheet Holidays
A1: STATUTORY HOLIDAYS
A2: INPUT. Used by WORKDAY() so pickup and reissue dates never land on a holiday.
A4: Holiday | B4: Date | C4: Notes
A5: New Year's Day | B5: 45658
A6: Family Day (Ontario) | B6: 45705
A7: Good Friday | B7: 45765
A8: Easter Monday | B8: 45768
A9: Victoria Day | B9: 45796
A10: Canada Day | B10: 45839
A11: Civic Holiday (optional) | B11: 45873
A12: Labour Day | B12: 45901
A13: National Day for Truth and Reconciliation | B13: 45930
A14: Thanksgiving Day | B14: 45943
A15: Remembrance Day | B15: 45962
A16: Christmas Day | B16: 46016
A17: Boxing Day | B17: 46017

Sheet Receipts
A1: RECEIPTS · GOODS-IN LEDGER
A2: INPUT. One row per lot received. Yellow columns are typed; the rest calculate.
A4: Date Ordered | B4: Vendor Name | C4: Lot Number | D4: Item Name | E4: Item Type | F4: Size | G4: Qty Received | H4: Expiry Date | I4: Date Received | J4: Unit Rate | K4: Received Value
A5: 46112 | B5: Admin Coordinator | C5: N955003713 | D5: 1804 N95 Mask | E5: =IF($D5="","",IFERROR(INDEX(Items!$B$5:$B$597,MATCH($D5,Items!$A$5:$A$597,0)),"⚠ not in Items")) -> Masks | F5: =IF($D5="","",IFERROR(INDEX(Items!$C$5:$C$597,MATCH($D5,Items!$A$5:$A$597,0)),"")) -> One Size | G5: 40 | H5: 46235 | I5: 46113 | J5: =IF($D5="","",IFERROR(INDEX(Items!$D$5:$D$597,MATCH($D5,Items!$A$5:$A$597,0)),"")) -> 2.05 | K5: =IF(OR($G5="",$J5=""),"",$G5*$J5) -> 82
A6: 46112 | B6: Admin Coordinator | C6: N955003716 | D6: 1860 N95 Mask | E6: =IF($D6="","",IFERROR(INDEX(Items!$B$5:$B$597,MATCH($D6,Items!$A$5:$A$597,0)),"⚠ not in Items")) -> Masks | F6: =IF($D6="","",IFERROR(INDEX(Items!$C$5:$C$597,MATCH($D6,Items!$A$5:$A$597,0)),"")) -> One Size | G6: 10840 | H6: 46235 | I6: 46113 | J6: =IF($D6="","",IFERROR(INDEX(Items!$D$5:$D$597,MATCH($D6,Items!$A$5:$A$597,0)),"")) -> 2.05 | K6: =IF(OR($G6="",$J6=""),"",$G6*$J6) -> 22222
A7: 46112 | B7: Admin Coordinator | C7: N955003715 | D7: 1860S N95 Mask | E7: =IF($D7="","",IFERROR(INDEX(Items!$B$5:$B$597,MATCH($D7,Items!$A$5:$A$597,0)),"⚠ not in Items")) -> Masks | F7: =IF($D7="","",IFERROR(INDEX(Items!$C$5:$C$597,MATCH($D7,Items!$A$5:$A$597,0)),"")) -> One Size | G7: 9835 | H7: 46235 | I7: 46113 | J7: =IF($D7="","",IFERROR(INDEX(Items!$D$5:$D$597,MATCH($D7,Items!$A$5:$A$597,0)),"")) -> 2.05 | K7: =IF(OR($G7="",$J7=""),"",$G7*$J7) -> 20161.75
A8: 46112 | B8: Admin Coordinator | C8: N955003718 | D8: 1870 N95 Mask | E8: =IF($D8="","",IFERROR(INDEX(Items!$B$5:$B$597,MATCH($D8,Items!$A$5:$A$597,0)),"⚠ not in Items")) -> Masks | F8: =IF($D8="","",IFERROR(INDEX(Items!$C$5:$C$597,MATCH($D8,Items!$A$5:$A$597,0)),"")) -> One Size | G8: 230 | H8: 46235 | I8: 46113 | J8: =IF($D8="","",IFERROR(INDEX(Items!$D$5:$D$597,MATCH($D8,Items!$A$5:$A$597,0)),"")) -> 2.05 | K8: =IF(OR($G8="",$J8=""),"",$G8*$J8) -> 471.5
A9: 46112 | B9: Admin Coordinator | C9: N955003717 | D9: 1870+ N95 Mask | E9: =IF($D9="","",IFERROR(INDEX(Items!$B$5:$B$597,MATCH($D9,Items!$A$5:$A$597,0)),"⚠ not in Items")) -> Masks | F9: =IF($D9="","",IFERROR(INDEX(Items!$C$5:$C$597,MATCH($D9,Items!$A$5:$A$597,0)),"")) -> One Size | G9: 18945 | H9: 46235 | I9: 46113 | J9: =IF($D9="","",IFERROR(INDEX(Items!$D$5:$D$597,MATCH($D9,Items!$A$5:$A$597,0)),"")) -> 2.05 | K9: =IF(OR($G9="",$J9=""),"",$G9*$J9) -> 38837.25
A10: 46112 | B10: Admin Coordinator | C10: N955003712 | D10: 8110S N95 Mask | E10: =IF($D10="","",IFERROR(INDEX(Items!$B$5:$B$597,MATCH($D10,Items!$A$5:$A$597,0)),"⚠ not in Items")) -> Masks | F10: =IF($D10="","",IFERROR(INDEX(Items!$C$5:$C$597,MATCH($D10,Items!$A$5:$A$597,0)),"")) -> One Size | G10: 3815 | H10: 46235 | I10: 46113 | J10: =IF($D10="","",IFERROR(INDEX(Items!$D$5:$D$597,MATCH($D10,Items!$A$5:$A$597,0)),"")) -> 1.45 | K10: =IF(OR($G10="",$J10=""),"",$G10*$J10) -> 5531.75
A11: 46112 | B11: Admin Coordinator | C11: N955003714 | D11: 8210 N95 Mask | E11: =IF($D11="","",IFERROR(INDEX(Items!$B$5:$B$597,MATCH($D11,Items!$A$5:$A$597,0)),"⚠ not in Items")) -> Masks | F11: =IF($D11="","",IFERROR(INDEX(Items!$C$5:$C$597,MATCH($D11,Items!$A$5:$A$597,0)),"")) -> One Size | G11: 17485 | H11: 46235 | I11: 46113 | J11: =IF($D11="","",IFERROR(INDEX(Items!$D$5:$D$597,MATCH($D11,Items!$A$5:$A$597,0)),"")) -> 1.45 | K11: =IF(OR($G11="",$J11=""),"",$G11*$J11) -> 25353.25
A12: 46112 | B12: Admin Coordinator | C12: N955003711 | D12: 9210+ N95 Mask | E12: =IF($D12="","",IFERROR(INDEX(Items!$B$5:$B$597,MATCH($D12,Items!$A$5:$A$597,0)),"⚠ not in Items")) -> Masks | F12: =IF($D12="","",IFERROR(INDEX(Items!$C$5:$C$597,MATCH($D12,Items!$A$5:$A$597,0)),"")) -> One Size | G12: 0 | H12: 46235 | I12: 46113 | J12: =IF($D12="","",IFERROR(INDEX(Items!$D$5:$D$597,MATCH($D12,Items!$A$5:$A$597,0)),"")) -> 1.45 | K12: =IF(OR($G12="",$J12=""),"",$G12*$J12) -> 0
A13: 46112 | B13: Admin Coordinator | C13: 4600093677 | D13: Alcohol Swab | E13: =IF($D13="","",IFERROR(INDEX(Items!$B$5:$B$597,MATCH($D13,Items!$A$5:$A$597,0)),"⚠ not in Items")) -> IPAC | F13: =IF($D13="","",IFERROR(INDEX(Items!$C$5:$C$597,MATCH($D13,Items!$A$5:$A$597,0)),"")) -> Box | G13: 1000 | H13: 46387 | I13: 46113 | J13: =IF($D13="","",IFERROR(INDEX(Items!$D$5:$D$597,MATCH($D13,Items!$A$5:$A$597,0)),"")) -> 3.25 | K13: =IF(OR($G13="",$J13=""),"",$G13*$J13) -> 3250
A14: 46112 | B14: Admin Coordinator | C14: BWMALM143200-0 | D14: BP CUFF | E14: =IF($D14="","",IFERROR(INDEX(Items!$B$5:$B$597,MATCH($D14,Items!$A$5:$A$597,0)),"⚠ not in Items")) -> Equipment | F14: =IF($D14="","",IFERROR(INDEX(Items!$C$5:$C$597,MATCH($D14,Items!$A$5:$A$597,0)),"")) -> Adult Regular | G14: 2 | H14: 47032 | I14: 46113 | J14: =IF($D14="","",IFERROR(INDEX(Items!$D$5:$D$597,MATCH($D14,Items!$A$5:$A$597,0)),"")) -> 35 | K14: =IF(OR($G14="",$J14=""),"",$G14*$J14) -> 70
A15: 46112 | B15: Admin Coordinator | C15: N9550025 | D15: CAN99 | E15: =IF($D15="","",IFERROR(INDEX(Items!$B$5:$B$597,MATCH($D15,Items!$A$5:$A$597,0)),"⚠ not in Items")) -> Masks | F15: =IF($D15="","",IFERROR(INDEX(Items!$C$5:$C$597,MATCH($D15,Items!$A$5:$A$597,0)),"")) -> One Size | G15: 25 | H15: 46235 | I15: 46113 | J15: =IF($D15="","",IFERROR(INDEX(Items!$D$5:$D$597,MATCH($D15,Items!$A$5:$A$597,0)),"")) -> 1.35 | K15: =IF(OR($G15="",$J15=""),"",$G15*$J15) -> 33.75
A16: 46112 | B16: Admin Coordinator | C16: ICCSS54321 | D16: CSS Ice Cleats Large | E16: =IF($D16="","",IFERROR(INDEX(Items!$B$5:$B$597,MATCH($D16,Items!$A$5:$A$597,0)),"⚠ not in Items")) -> PPE | F16: =IF($D16="","",IFERROR(INDEX(Items!$C$5:$C$597,MATCH($D16,Items!$A$5:$A$597,0)),"")) -> Large | G16: 0 | H16: 47386 | I16: 46113 | J16: =IF($D16="","",IFERROR(INDEX(Items!$D$5:$D$597,MATCH($D16,Items!$A$5:$A$597,0)),"")) -> 145.98 | K16: =IF(OR($G16="",$J16=""),"",$G16*$J16) -> 0
A17: 46112 | B17: Admin Coordinator | C17: ICCSS4321 | D17: CSS Ice Cleats Medium | E17: =IF($D17="","",IFERROR(INDEX(Items!$B$5:$B$597,MATCH($D17,Items!$A$5:$A$597,0)),"⚠ not in Items")) -> PPE | F17: =IF($D17="","",IFERROR(INDEX(Items!$C$5:$C$597,MATCH($D17,Items!$A$5:$A$597,0)),"")) -> Medium | G17: 0 | H17: 47386 | I17: 46113 | J17: =IF($D17="","",IFERROR(INDEX(Items!$D$5:$D$597,MATCH($D17,Items!$A$5:$A$597,0)),"")) -> 145.98 | K17: =IF(OR($G17="",$J17=""),"",$G17*$J17) -> 0
A18: 46112 | B18: Admin Coordinator | C18: ICCSS321 | D18: CSS Ice Cleats Small | E18: =IF($D18="","",IFERROR(INDEX(Items!$B$5:$B$597,MATCH($D18,Items!$A$5:$A$597,0)),"⚠ not in Items")) -> PPE | F18: =IF($D18="","",IFERROR(INDEX(Items!$C$5:$C$597,MATCH($D18,Items!$A$5:$A$597,0)),"")) -> Small | G18: 0 | H18: 47386 | I18: 46113 | J18: =IF($D18="","",IFERROR(INDEX(Items!$D$5:$D$597,MATCH($D18,Items!$A$5:$A$597,0)),"")) -> 145.98 | K18: =IF(OR($G18="",$J18=""),"",$G18*$J18) -> 0
A19: 46112 | B19: Admin Coordinator | C19: ICCSS654321 | D19: CSS Ice Cleats X Large | E19: =IF($D19="","",IFERROR(INDEX(Items!$B$5:$B$597,MATCH($D19,Items!$A$5:$A$597,0)),"⚠ not in Items")) -> PPE | F19: =IF($D19="","",IFERROR(INDEX(Items!$C$5:$C$597,MATCH($D19,Items!$A$5:$A$597,0)),"")) -> X-Large | G19: 0 | H19: 47386 | I19: 46113 | J19: =IF($D19="","",IFERROR(INDEX(Items!$D$5:$D$597,MATCH($D19,Items!$A$5:$A$597,0)),"")) -> 145.98 | K19: =IF(OR($G19="",$J19=""),"",$G19*$J19) -> 0
A20: 46112 | B20: Admin Coordinator | C20: 3146837-7000 | D20: DNR | E20: =IF($D20="","",IFERROR(INDEX(Items!$B$5:$B$597,MATCH($D20,Items!$A$5:$A$597,0)),"⚠ not in Items")) -> Forms | F20: =IF($D20="","",IFERROR(INDEX(Items!$C$5:$C$597,MATCH($D20,Items!$A$5:$A$597,0)),"")) -> Standard | G20: 153 | H20: 47046 | I20: 46113 | J20: =IF($D20="","",IFERROR(INDEX(Items!$D$5:$D$597,MATCH($D20,Items!$A$5:$A$597,0)),"")) -> 0 | K20: =IF(OR($G20="",$J20=""),"",$G20*$J20) -> 0
A21: 46112 | B21: Admin Coordinator | C21: LYSL500290 | D21: Disinfectant Wipes | E21: =IF($D21="","",IFERROR(INDEX(Items!$B$5:$B$597,MATCH($D21,Items!$A$5:$A$597,0)),"⚠ not in Items")) -> Wipes | F21: =IF($D21="","",IFERROR(INDEX(Items!$C$5:$C$597,MATCH($D21,Items!$A$5:$A$597,0)),"")) -> 80 | G21: 192080 | H21: 47046 | I21: 46113 | J21: =IF($D21="","",IFERROR(INDEX(Items!$D$5:$D$597,MATCH($D21,Items!$A$5:$A$597,0)),"")) -> 0.1 | K21: =IF(OR($G21="",$J21=""),"",$G21*$J21) -> 19208
A22: 46112 | B22: Admin Coordinator | C22: EDITH001 | D22: EDITH | E22: =IF($D22="","",IFERROR(INDEX(Items!$B$5:$B$597,MATCH($D22,Items!$A$5:$A$597,0)),"⚠ not in Items")) -> Forms | F22: =IF($D22="","",IFERROR(INDEX(Items!$C$5:$C$597,MATCH($D22,Items!$A$5:$A$597,0)),"")) -> Standard | G22: 85 | H22: 47046 | I22: 46113 | J22: =IF($D22="","",IFERROR(INDEX(Items!$D$5:$D$597,MATCH($D22,Items!$A$5:$A$597,0)),"")) -> 0 | K22: =IF(OR($G22="",$J22=""),"",$G22*$J22) -> 0
A23: 46112 | B23: Admin Coordinator | C23: 50037 | D23: Epinephrine | E23: =IF($D23="","",IFERROR(INDEX(Items!$B$5:$B$597,MATCH($D23,Items!$A$5:$A$597,0)),"⚠ not in Items")) -> Drug | F23: =IF($D23="","",IFERROR(INDEX(Items!$C$5:$C$597,MATCH($D23,Items!$A$5:$A$597,0)),"")) -> 1 Amp | G23: 48 | H23: 46538 | I23: 46113 | J23: =IF($D23="","",IFERROR(INDEX(Items!$D$5:$D$597,MATCH($D23,Items!$A$5:$A$597,0)),"")) -> 5.9 | K23: =IF(OR($G23="",$J23=""),"",$G23*$J23) -> 283.2
A24: 46112 | B24: Admin Coordinator | C24: A000065867 | D24: Epinephrine | E24: =IF($D24="","",IFERROR(INDEX(Items!$B$5:$B$597,MATCH($D24,Items!$A$5:$A$597,0)),"⚠ not in Items")) -> Drug | F24: =IF($D24="","",IFERROR(INDEX(Items!$C$5:$C$597,MATCH($D24,Items!$A$5:$A$597,0)),"")) -> 1 Amp | G24: 0 | H24: 46022 | I24: 46113 | J24: =IF($D24="","",IFERROR(INDEX(Items!$D$5:$D$597,MATCH($D24,Items!$A$5:$A$597,0)),"")) -> 5.9 | K24: =IF(OR($G24="",$J24=""),"",$G24*$J24) -> 0
A25: 46112 | B25: Admin Coordinator | C25: 0417HIC25-0 | D25: Gloves - Large | E25: =IF($D25="","",IFERROR(INDEX(Items!$B$5:$B$597,MATCH($D25,Items!$A$5:$A$597,0)),"⚠ not in Items")) -> Gloves | F25: =IF($D25="","",IFERROR(INDEX(Items!$C$5:$C$597,MATCH($D25,Items!$A$5:$A$597,0)),"")) -> Large | G25: 2000 | H25: 46285 | I25: 46113 | J25: =IF($D25="","",IFERROR(INDEX(Items!$D$5:$D$597,MATCH($D25,Items!$A$5:$A$597,0)),"")) -> 0.055 | K25: =IF(OR($G25="",$J25=""),"",$G25*$J25) -> 110
A26: 46112 | B26: Admin Coordinator | C26: 0417HIC25-1 | D26: Gloves - Large | E26: =IF($D26="","",IFERROR(INDEX(Items!$B$5:$B$597,MATCH($D26,Items!$A$5:$A$597,0)),"⚠ not in Items")) -> Gloves | F26: =IF($D26="","",IFERROR(INDEX(Items!$C$5:$C$597,MATCH($D26,Items!$A$5:$A$597,0)),"")) -> Large | G26: 7500 | H26: 46292 | I26: 46113 | J26: =IF($D26="","",IFERROR(INDEX(Items!$D$5:$D$597,MATCH($D26,Items!$A$5:$A$597,0)),"")) -> 0.055 | K26: =IF(OR($G26="",$J26=""),"",$G26*$J26) -> 412.5
A27: 46112 | B27: Admin Coordinator | C27: LG5003002 | D27: Gloves - Large | E27: =IF($D27="","",IFERROR(INDEX(Items!$B$5:$B$597,MATCH($D27,Items!$A$5:$A$597,0)),"⚠ not in Items")) -> Gloves | F27: =IF($D27="","",IFERROR(INDEX(Items!$C$5:$C$597,MATCH($D27,Items!$A$5:$A$597,0)),"")) -> Large | G27: 0 | H27: 46135 | I27: 46113 | J27: =IF($D27="","",IFERROR(INDEX(Items!$D$5:$D$597,MATCH($D27,Items!$A$5:$A$597,0)),"")) -> 0.055 | K27: =IF(OR($G27="",$J27=""),"",$G27*$J27) -> 0
A28: 46112 | B28: Admin Coordinator | C28: LG5003102 | D28: Gloves - Large | E28: =IF($D28="","",IFERROR(INDEX(Items!$B$5:$B$597,MATCH($D28,Items!$A$5:$A$597,0)),"⚠ not in Items")) -> Gloves | F28: =IF($D28="","",IFERROR(INDEX(Items!$C$5:$C$597,MATCH($D28,Items!$A$5:$A$597,0)),"")) -> Large | G28: 0 | H28: 46159 | I28: 46113 | J28: =IF($D28="","",IFERROR(INDEX(Items!$D$5:$D$597,MATCH($D28,Items!$A$5:$A$597,0)),"")) -> 0.055 | K28: =IF(OR($G28="",$J28=""),"",$G28*$J28) -> 0
A29: 46112 | B29: Admin Coordinator | C29: LG5003202 | D29: Gloves - Large | E29: =IF($D29="","",IFERROR(INDEX(Items!$B$5:$B$597,MATCH($D29,Items!$A$5:$A$597,0)),"⚠ not in Items")) -> Gloves | F29: =IF($D29="","",IFERROR(INDEX(Items!$C$5:$C$597,MATCH($D29,Items!$A$5:$A$597,0)),"")) -> Large | G29: 0 | H29: 46162 | I29: 46113 | J29: =IF($D29="","",IFERROR(INDEX(Items!$D$5:$D$597,MATCH($D29,Items!$A$5:$A$597,0)),"")) -> 0.055 | K29: =IF(OR($G29="",$J29=""),"",$G29*$J29) -> 0
A30: 46112 | B30: Admin Coordinator | C30: LG5003203 | D30: Gloves - Large | E30: =IF($D30="","",IFERROR(INDEX(Items!$B$5:$B$597,MATCH($D30,Items!$A$5:$A$597,0)),"⚠ not in Items")) -> Gloves | F30: =IF($D30="","",IFERROR(INDEX(Items!$C$5:$C$597,MATCH($D30,Items!$A$5:$A$597,0)),"")) -> Large | G30: 0 | H30: 46162 | I30: 46113 | J30: =IF($D30="","",IFERROR(INDEX(Items!$D$5:$D$597,MATCH($D30,Items!$A$5:$A$597,0)),"")) -> 0.055 | K30: =IF(OR($G30="",$J30=""),"",$G30*$J30) -> 0
A31: 46112 | B31: Admin Coordinator | C31: LG5003302 | D31: Gloves - Large | E31: =IF($D31="","",IFERROR(INDEX(Items!$B$5:$B$597,MATCH($D31,Items!$A$5:$A$597,0)),"⚠ not in Items")) -> Gloves | F31: =IF($D31="","",IFERROR(INDEX(Items!$C$5:$C$597,MATCH($D31,Items!$A$5:$A$597,0)),"")) -> Large | G31: 0 | H31: 46188 | I31: 46113 | J31: =IF($D31="","",IFERROR(INDEX(Items!$D$5:$D$597,MATCH($D31,Items!$A$5:$A$597,0)),"")) -> 0.055 | K31: =IF(OR($G31="",$J31=""),"",$G31*$J31) -> 0
A32: 46112 | B32: Admin Coordinator | C32: ZIM506129477-0 | D32: Gloves - Large | E32: =IF($D32="","",IFERROR(INDEX(Items!$B$5:$B$597,MATCH($D32,Items!$A$5:$A$597,0)),"⚠ not in Items")) -> Gloves | F32: =IF($D32="","",IFERROR(INDEX(Items!$C$5:$C$597,MATCH($D32,Items!$A$5:$A$597,0)),"")) -> Large | G32: 0 | H32: 46179 | I32: 46113 | J32: =IF($D32="","",IFERROR(INDEX(Items!$D$5:$D$597,MATCH($D32,Items!$A$5:$A$597,0)),"")) -> 0.055 | K32: =IF(OR($G32="",$J32=""),"",$G32*$J32) -> 0
A33: 46112 | B33: Admin Coordinator | C33: ZIM506129477-1 | D33: Gloves - Large | E33: =IF($D33="","",IFERROR(INDEX(Items!$B$5:$B$597,MATCH($D33,Items!$A$5:$A$597,0)),"⚠ not in Items")) -> Gloves | F33: =IF($D33="","",IFERROR(INDEX(Items!$C$5:$C$597,MATCH($D33,Items!$A$5:$A$597,0)),"")) -> Large | G33: 0 | H33: 46216 | I33: 46113 | J33: =IF($D33="","",IFERROR(INDEX(Items!$D$5:$D$597,MATCH($D33,Items!$A$5:$A$597,0)),"")) -> 0.055 | K33: =IF(OR($G33="",$J33=""),"",$G33*$J33) -> 0
A34: 46112 | B34: Admin Coordinator | C34: ZIM509135933-0 | D34: Gloves - Large | E34: =IF($D34="","",IFERROR(INDEX(Items!$B$5:$B$597,MATCH($D34,Items!$A$5:$A$597,0)),"⚠ not in Items")) -> Gloves | F34: =IF($D34="","",IFERROR(INDEX(Items!$C$5:$C$597,MATCH($D34,Items!$A$5:$A$597,0)),"")) -> Large | G34: 0 | H34: 46223 | I34: 46113 | J34: =IF($D34="","",IFERROR(INDEX(Items!$D$5:$D$597,MATCH($D34,Items!$A$5:$A$597,0)),"")) -> 0.055 | K34: =IF(OR($G34="",$J34=""),"",$G34*$J34) -> 0
A35: 46112 | B35: Admin Coordinator | C35: ZIM509135933-1 | D35: Gloves - Large | E35: =IF($D35="","",IFERROR(INDEX(Items!$B$5:$B$597,MATCH($D35,Items!$A$5:$A$597,0)),"⚠ not in Items")) -> Gloves | F35: =IF($D35="","",IFERROR(INDEX(Items!$C$5:$C$597,MATCH($D35,Items!$A$5:$A$597,0)),"")) -> Large | G35: 0 | H35: 46244 | I35: 46113 | J35: =IF($D35="","",IFERROR(INDEX(Items!$D$5:$D$597,MATCH($D35,Items!$A$5:$A$597,0)),"")) -> 0.055 | K35: =IF(OR($G35="",$J35=""),"",$G35*$J35) -> 0
... A157: 46164 | B157: Global PPE Distributors | C157: ZIM511139904-3 | D157: Gloves - Large | E157: =IF($D157="","",IFERROR(INDEX(Items!$B$5:$B$597,MATCH($D157,Items!$A$5:$A$597,0)),"⚠ not in Items")) -> Gloves | F157: =IF($D157="","",IFERROR(INDEX(Items!$C$5:$C$597,MATCH($D157,Items!$A$5:$A$597,0)),"")) -> Large | G157: 2500 | H157: 46352 | I157: 46168 | J157: =IF($D157="","",IFERROR(INDEX(Items!$D$5:$D$597,MATCH($D157,Items!$A$5:$A$597,0)),"")) -> 0.055 | K157: =IF(OR($G157="",$J157=""),"",$G157*$J157) -> 137.5
A158: 46164 | B158: Regional Supply Co | C158: 3024 | D158: Shoe Covers | E158: =IF($D158="","",IFERROR(INDEX(Items!$B$5:$B$597,MATCH($D158,Items!$A$5:$A$597,0)),"⚠ not in Items")) -> IPAC | F158: =IF($D158="","",IFERROR(INDEX(Items!$C$5:$C$597,MATCH($D158,Items!$A$5:$A$597,0)),"")) -> Regular | G158: 300 | H158: 46718 | I158: 46169 | J158: =IF($D158="","",IFERROR(INDEX(Items!$D$5:$D$597,MATCH($D158,Items!$A$5:$A$597,0)),"")) -> 0.2 | K158: =IF(OR($G158="",$J158=""),"",$G158*$J158) -> 60
A159: 46164 | B159: Regional Supply Co | C159: 20-21734-4 | D159: Hand Sanitizer OS | E159: =IF($D159="","",IFERROR(INDEX(Items!$B$5:$B$597,MATCH($D159,Items!$A$5:$A$597,0)),"⚠ not in Items")) -> Sanitizer | F159: =IF($D159="","",IFERROR(INDEX(Items!$C$5:$C$597,MATCH($D159,Items!$A$5:$A$597,0)),"")) -> 236 ML | G159: 60 | H159: 46811 | I159: 46169 | J159: =IF($D159="","",IFERROR(INDEX(Items!$D$5:$D$597,MATCH($D159,Items!$A$5:$A$597,0)),"")) -> 0.0001 | K159: =IF(OR($G159="",$J159=""),"",$G159*$J159) -> 0.006
A160: 46164 | B160: Regional Supply Co | C160: 315JIC25 | D160: Gloves - Medium | E160: =IF($D160="","",IFERROR(INDEX(Items!$B$5:$B$597,MATCH($D160,Items!$A$5:$A$597,0)),"⚠ not in Items")) -> Gloves | F160: =IF($D160="","",IFERROR(INDEX(Items!$C$5:$C$597,MATCH($D160,Items!$A$5:$A$597,0)),"")) -> Medium | G160: 2500 | H160: 46353 | I160: 46169 | J160: =IF($D160="","",IFERROR(INDEX(Items!$D$5:$D$597,MATCH($D160,Items!$A$5:$A$597,0)),"")) -> 0.055 | K160: =IF(OR($G160="",$J160=""),"",$G160*$J160) -> 137.5
A161: 46171 | B161: Global PPE Distributors | C161: ZIM510137962-1 | D161: Gloves - Medium | E161: =IF($D161="","",IFERROR(INDEX(Items!$B$5:$B$597,MATCH($D161,Items!$A$5:$A$597,0)),"⚠ not in Items")) -> Gloves | F161: =IF($D161="","",IFERROR(INDEX(Items!$C$5:$C$597,MATCH($D161,Items!$A$5:$A$597,0)),"")) -> Medium | G161: 7500 | H161: 46364 | I161: 46181 | J161: =IF($D161="","",IFERROR(INDEX(Items!$D$5:$D$597,MATCH($D161,Items!$A$5:$A$597,0)),"")) -> 0.055 | K161: =IF(OR($G161="",$J161=""),"",$G161*$J161) -> 412.5
A162: 46171 | B162: Global PPE Distributors | C162: ZIM601144366-0 | D162: Gloves - Small | E162: =IF($D162="","",IFERROR(INDEX(Items!$B$5:$B$597,MATCH($D162,Items!$A$5:$A$597,0)),"⚠ not in Items")) -> Gloves | F162: =IF($D162="","",IFERROR(INDEX(Items!$C$5:$C$597,MATCH($D162,Items!$A$5:$A$597,0)),"")) -> Small | G162: 2500 | H162: 46364 | I162: 46181 | J162: =IF($D162="","",IFERROR(INDEX(Items!$D$5:$D$597,MATCH($D162,Items!$A$5:$A$597,0)),"")) -> 0.055 | K162: =IF(OR($G162="",$J162=""),"",$G162*$J162) -> 137.5
...

Sheet Issues
A1: ISSUES · STAFF DISPENSING LEDGER
A2: INPUT. One row per item dispensed. Pick the Staff Name from the dropdown — Staff ID, Role and Area fill in automatically. Enter Tracking ID when collected and Status updates itself.
A4: Order Date | B4: Staff ID | C4: Staff Name (pick) | D4: Role | E4: Area | F4: Item Name | G4: Item Type | H4: Size | I4: Standard Issue | J4: Qty Issued | K4: Unit Rate | L4: Line Cost | M4: Lot Number | N4: Pickup Date | O4: Next Scheduled | P4: Tracking ID | Q4: Status | R4: Month | S4: Units This Month (Staff/Item) | T4: Monthly Quota | U4: Quota Status | V4: Breach Key | W4: First Breach | X4: Alert Row | Y4: TL Approval | Z4: Approved By / Ref | AA4: Staff Email | AB4: Notice Type | AC4: Email Subject | AD4: Email Body | AE4: Mailto Link | AF4: Draft in Outlook | AG4: Staff First Name | AH4: Staff Full Name | AI4: Lot Override | AJ4: Cum Units (Item) | AK4: Line Start Unit | AL4: FEFO Lot (Auto) | AM4: Lot At Line End | AN4: Lot Check | AO4: Qty Override
